Workbook

Sheet Parámetros
B2: PARAMETROS
B3: Parametros del Transceiver TQD017 [400Gbps] | C3: Valores | D3: Variabilidad
B4: Potencia maxima de salida (dBm) | C4: 1
B5: Potencia minima de salida (dBm) | C5: -9
B6: Dispersion Cromatica (ps/nm) | C6: 12000
B7: Sensibilidad en el receptor para OSNR >= 23,5dB (dB) | C7: -14 | E7: Relacionada con E-12 | G7: Se suele llegar con -7,8 dBm
B8: Potencia maxima de entrada en el receptor (dBm) | C8: 13
B9: OSNR del transmisor a 0,1nm (dB) | C9: 38
B10: OSNR requerida | C10: 23.5
B11: Tolerancia PMD (ps) | C11: 10 | E11: En transceivers modernos que usan DP-16QAM suele ser 10 [ps]
B12: GSNR a 0,1nm (dB) | C12: 23.5 | E12: OSNR de recepcion con -14dBm
B13: Bo (GHz) | C13: 12.5 | E13: Normalizado a 0,1nm
B14: Multiplexador DCP-R-9D
B15: VOA ajustable | D15: - (0 a 19) dB | E15: Cantidad Canales = 40
B16: Atenuacion MUX+/DEMUX+ | C16: 10
B17: Preamplificador Integrado
B18: Sensibilidad máxima LINE (IN) (dBm) | C18: -25 | E18: Tratamos siempre de llegar al pre con -18,8 dB | H18: 18.8
B19: Potencia de entrada mínima por canal (dBm) | C19: -41.02 | E19: Sensibilidad maxima (LINE IN) - 10*log10(Cantidad Canales) | I19: 10*log10(40)=16,02
B20: Ganancia del preamplificador (dB) | C20: 21
B21: Potencia de salida máxima SIG (OUT) (dBm) | C21: 20
B22: Potencia de entrada máxima por canal (dBm) para 22dB ganancia | C22: -18.02 | E22: Potencia de entrada maxima total - 10*log10(Cantidad Canales) | I22: Potencia de entrada maxima total = Potencia de salida maxima (SIG OUT) - Ganancia
B23: Figura de Ruido preamplificador (dB) | C23: 5.5
B24: Booster Integrado
B25: Sensibilidad máxima SIG (IN) (dBm) | C25: -25 | E25: Tratamos siempre de llegar al booster con -17,8 dB
B26: Potencia de entrada mínima por canal (dBm) | C26: -41.02
B27: Ganancia Booster Amplifier (dB) | C27: 21.5
B28: Potencia de salida máxima LINE (OUT) (dBm) | C28: 20
B29: Potencia de entrada máxima por canal (dBm) para 21,5dB ganancia | C29: -17.52 | E29: Potencia de entrada maxima total - 10*log10(Cantidad Canales) | I29: Potencia de entrada maxima total = Potencia de salida maxima (LINE OUT) - Ganancia
B30: Figura de Ruido booster (dB) | C30: 6 | E30: Tratamos de salir del Booster con 2,5 dB por canal | I30: =2.5 -> 2.5
B31: Parametros del Amplificador de Linea (OLA2525)
B32: VOA ajustable
B33: Sensibilidad máxima LINE (IN) (dBm) | C33: -28
B34: Potencia de entrada mínima por canal (dBm) | C34: -44.02
B35: Ganancia del amplificador (dB) | C35: 25
B36: Potencia de salida máxima LINE (OUT) (dBm) | C36: 21.5
B37: Potencia de entrada máxima por canal (dBm) para 25dB ganancia | C37: -19.52 | E37: Potencia de entrada maxima total - 10*log10(Cantidad Canales) | I37: Potencia de entrada maxima total = Potencia de salida maxima (LINE OUT) - Ganancia
B38: Figura de Ruido (dB) | C38: 5.5
B39: Parametros de la fibra Corning SMF-28
B40: Atenuación (db/km) | C40: 0.18
B41: Atenuación (dB/km) + 0,05 empalmes fusion | C41: 0.185
...

Sheet Enlace Comprometido
A1: Benavidez - Rosario | D1: calculos normalizados a 0,1 nm
A2: Presupuesto de Potencia | B2: Distancia (km) | C2: Atenuación por km | D2: Amplificación/Atenuación (dB) | E2: Potencia acumulada (dBm) | F2: 400 Gbps / Limite | G2: NF (dB) | H2: OSNR canal (dB) | I2: OSNR canal (veces) | J2: OSNR acumulada (dB) | K2: OSNR acumulada (veces) | L2: 1/GSNR NL | M2: GSNR NL (dB) | N2: GSNR NL (veces) | O2: GSNR NL acumulada (dB) | P2: GSNR NL acumulada (veces) | Q2: GSNR Total (dB)
A3: Benavidez | F3: 400
A4: Transceiver | E4: =Parámetros!C5 -> -9 | H4: =Parámetros!C9 -> 38 | I4: =10^(H4/10) -> 6309.5734 | J4: =H4 -> 38 | K4: =10^(J4/10) -> 6309.5734 | L4: - | M4: - | N4: - | O4: - | P4: -
A5: MUX+ | D5: =-Parámetros!C16 -> -10 | E5: =D5+E4 -> -19 | F5: =Parámetros!C29 -> -17.52
A6: Amplificador Booster | D6: =Parámetros!C27 -> 21.5 | E6: =D6+E5 -> 2.5 | G6: =Parámetros!C30 -> 6 | H6: =E5+158.9-10*LOG10(Parámetros!C13*10^9)-G6 -> 32.9309 | I6: =10^(H6/10) -> 1963.7671 | J6: =10*LOG10(K6) -> 31.754091 | K6: =1/((1/K4)+(1/I6)) -> 1497.6457 | L6: =(2/3)^3*Parámetros!C56*(Parámetros!C57)^2*'No linealidades'!D3*(10^(E7/10)*0.001)^2*LOG10(PI()^2*ABS(Parámetros!C58*10^(-24))*'No linealidades'!D3*(Parámetros!C59)^2*Parámetros!C60^2)/(PI()*ABS(Parámetros!C58*10^(-24))*Parámetros!C60^3)*Parámetros!C13*10^9 -> 4.9024839e-05 | M6: =10*LOG10(N6) -> 43.095838 | N6: =1/L6 -> 20397.823 | O6: =M6 -> 43.095838 | P6: =N6 -> 20397.823 | Q6: =10*LOG10(HARMEAN(K6,P6)/2) -> 31.446387
A7: VOA (Booster) | D7: 0 | E7: =D7+E6 -> 2.5
A8: Fibra | B8: 80 | C8: =Parámetros!C41 -> 0.185 | D8: =-B8*C8 -> -14.8 | E8: =D8+E7 -> -12.3 | F8: =IF(E8>=Parámetros!C18,"V","F") -> V
A9: Campana
A10: VOA (Line In) | D10: =-(E8+Parámetros!H18) -> -6.5 | E10: =E8+D10 -> -18.8 | F10: =Parámetros!C22 -> -18.02
A11: Preamplificador | D11: =Parámetros!C20 -> 21 | E11: =D11+E10 -> 2.2 | G11: =Parámetros!C23 -> 5.5 | H11: =E10+158.9-10*LOG10(Parámetros!C13*10^9)-G11 -> 33.6309 | I11: =10^(H11/10) -> 2307.2252 | J11: =10*LOG10(K11) -> 29.581591 | K11: =1/(1/I11+1/K6) -> 908.15326 | L11: - | M11: - | N11: - | O11: - | P11: - | Q11: =10*LOG10(HARMEAN(K11,P6)/2) -> 29.392415
A12: WSS+ (ROADM 1) | D12: =-Parámetros!C16 -> -10 | E12: =D12+E11 -> -7.8
A13: WSS+ (ROADM 2) | D13: =-Parámetros!C16 -> -10 | E13: =D13+E12 -> -17.8 | F13: =Parámetros!C29 -> -17.52
A14: Amplificador Booster | D14: =Parámetros!C27 -> 21.5 | E14: =D14+E13 -> 3.7 | G14: =Parámetros!C30 -> 6 | H14: =E13+158.9-10*LOG10(Parámetros!C13*10^9)-G14 -> 34.1309 | I14: =10^(H14/10) -> 2588.7493 | J14: =10*LOG10(K14) -> 28.275656 | K14: =1/(1/I14+1/K11) -> 672.30386 | L14: =(2/3)^3*Parámetros!C56*(Parámetros!C57)^2*'No linealidades'!D4*(10^(E15/10)*0.001)^2*LOG10(PI()^2*ABS(Parámetros!C58*10^(-24))*'No linealidades'!D4*(Parámetros!C59)^2*Parámetros!C60^2)/(PI()*ABS(Parámetros!C58*10^(-24))*Parámetros!C60^3)*Parámetros!C13*10^9 -> 1.9856792e-05 | M14: =10*LOG10(N14) -> 47.020909 | N14: =1/L14 -> 50360.603 | O14: =10*LOG10(P14) -> 41.618966 | P14: =HARMEAN(N6,N14)/2 -> 14517.659 | Q14: =10*LOG10(HARMEAN(K14,P14)/2) -> 28.079055
A15: VOA (Booster) | D15: =-(E14-Parámetros!I30) -> -1.2 | E15: =D15+E14 -> 2.5
A16: Fibra | B16: 13 | C16: =Parámetros!C41 -> 0.185 | D16: =-B16*C16 -> -2.405 | E16: =D16+E15 -> 0.095 | F16: =IF(E16>=Parámetros!C18,"V","F") -> V
A17: Zarate
A18: VOA (Line In) | D18: =-(E16+Parámetros!H18) -> -18.895 | E18: =E16+D18 -> -18.8 | F18: =Parámetros!C22 -> -18.02
A19: Preamplificador | D19: =Parámetros!C20 -> 21 | E19: =D19+E18 -> 2.2 | G19: =Parámetros!C23 -> 5.5 | H19: =E18+158.9-10*LOG10(Parámetros!C13*10^9)-G19 -> 33.6309 | I19: =10^(H19/10) -> 2307.2252 | J19: =10*LOG10(K19) -> 27.16508 | K19: =1/(1/I19+1/K14) -> 520.60456 | L19: - | M19: - | N19: - | O19: - | P19: - | Q19: =10*LOG10(HARMEAN(K19,P14)/2) -> 27.012069
A20: WSS+ (ROADM 1) | D20: =-Parámetros!C16 -> -10 | E20: =D20+E19 -> -7.8
A21: WSS+ (ROADM 2) | D21: =-Parámetros!C16 -> -10 | E21: =D21+E20 -> -17.8 | F21: =Parámetros!C29 -> -17.52
A22: Amplificador Booster | D22: =Parámetros!C27 -> 21.5 | E22: =D22+E21 -> 3.7 | G22: =Parámetros!C30 -> 6 | H22: =E21+158.9-10*LOG10(Parámetros!C13*10^9)-G22 -> 34.1309 | I22: =10^(H22/10) -> 2588.7493 | J22: =10*LOG10(K22) -> 26.369278 | K22: =1/(1/I22+1/K19) -> 433.43883 | L22: =(2/3)^3*Parámetros!C56*(Parámetros!C57)^2*'No linealidades'!D5*(10^(E23/10)*0.001)^2*LOG10(PI()^2*ABS(Parámetros!C58*10^(-24))*'No linealidades'!D5*(Parámetros!C59)^2*Parámetros!C60^2)/(PI()*ABS(Parámetros!C58*10^(-24))*Parámetros!C60^3)*Parámetros!C13*10^9 -> 4.7664792e-05 | M22: =10*LOG10(N22) -> 43.218023 | N22: =1/L22 -> 20979.846 | O22: =10*LOG10(P22) -> 39.335011 | P22: =HARMEAN(N6,N14,N22)/3 -> 8580.2719 | Q22: =10*LOG10(HARMEAN(K22,P22)/2) -> 26.155252
A23: VOA (Booster) | D23: =-(E22-Parámetros!I30) -> -1.2 | E23: =D23+E22 -> 2.5
A24: Fibra | B24: 67 | C24: =Parámetros!C41 -> 0.185 | D24: =-B24*C24 -> -12.395 | E24: =D24+E23 -> -9.895 | F24: =IF(E24>=Parámetros!C18,"V","F") -> V
A25: Baradero
A26: VOA (Line In) | D26: =-(E24+Parámetros!H18) -> -8.905 | E26: =E24+D26 -> -18.8 | F26: =Parámetros!C22 -> -18.02
A27: Preamplificador | D27: =Parámetros!C20 -> 21 | E27: =D27+E26 -> 2.2 | G27: =Parámetros!C23 -> 5.5 | H27: =E26+158.9-10*LOG10(Parámetros!C13*10^9)-G27 -> 33.6309 | I27: =10^(H27/10) -> 2307.2252 | J27: =10*LOG10(K27) -> 25.62162 | K27: =1/(1/I27+1/K22) -> 364.89003 | L27: - | M27: - | N27: - | O27: - | P27: - | Q27: =10*LOG10(HARMEAN(K27,P22)/2) -> 25.440748
A28: WSS+ (ROADM 1) | D28: =-Parámetros!C16 -> -10 | E28: =D28+E27 -> -7.8
A29: WSS+ (ROADM 2) | D29: =-Parámetros!C16 -> -10 | E29: =D29+E28 -> -17.8 | F29: =Parámetros!C29 -> -17.52
A30: Amplificador Booster | D30: =Parámetros!C27 -> 21.5 | E30: =D30+E29 -> 3.7 | G30: =Parámetros!C30 -> 6 | H30: =E29+158.9-10*LOG10(Parámetros!C13*10^9)-G30 -> 34.1309 | I30: =10^(H30/10) -> 2588.7493 | J30: =10*LOG10(K30) -> 25.048945 | K30: =1/(1/I30+1/K27) -> 319.81183 | L30: =(2/3)^3*Parámetros!C56*(Parámetros!C57)^2*'No linealidades'!D6*(10^(E31/10)*0.001)^2*LOG10(PI()^2*ABS(Parámetros!C58*10^(-24))*'No linealidades'!D6*(Parámetros!C59)^2*Parámetros!C60^2)/(PI()*ABS(Parámetros!C58*10^(-24))*Parámetros!C60^3)*Parámetros!C13*10^9 -> 3.7916598e-05 | M30: =10*LOG10(N30) -> 44.211706 | N30: =1/L30 -> 26373.674 | O30: =10*LOG10(P30) -> 38.111755 | P30: =HARMEAN(N6,N14,N22,N30)/4 -> 6474.0415 | Q30: =10*LOG10(HARMEAN(K30,P30)/2) -> 24.839538
A31: VOA (Booster) | D31: =-(E30-Parámetros!I30) -> -1.2 | E31: =D31+E30 -> 2.5
A32: Fibra | B32: 34 | C32: =Parámetros!C41 -> 0.185 | D32: =-B32*C32 -> -6.29 | E32: =D32+E31 -> -3.79 | F32: =IF(E32>=Parámetros!C18,"V","F") -> V
A33: San Pedro BsAs
A34: VOA (Line In) | D34: =-(E32+Parámetros!H18) -> -15.01 | E34: =D34+E32 -> -18.8 | F34: =Parámetros!C22 -> -18.02
A35: Preamplificador | D35: =Parámetros!C20 -> 21 | E35: =D35+E34 -> 2.2 | G35: =Parámetros!C23 -> 5.5 | H35: =E34+158.9-10*LOG10(Parámetros!C13*10^9)-G35 -> 33.6309 | I35: =10^(H35/10) -> 2307.2252 | J35: =10*LOG10(K35) -> 24.485183 | K35: =1/(1/I35+1/K30) -> 280.87839 | L35: - | M35: - | N35: - | O35: - | P35: - | Q35: =10*LOG10(HARMEAN(K35,P30)/2) -> 24.300736
A36: WSS+ (ROADM 1) | D36: =-Parámetros!C16 -> -10 | E36: =D36+E35 -> -7.8
A37: WSS+ (ROADM 2) | D37: =-Parámetros!C16 -> -10 | E37: =D37+E36 -> -17.8 | F37: =Parámetros!C29 -> -17.52
A38: Amplificador Booster | D38: =Parámetros!C27 -> 21.5 | E38: =D38+E37 -> 3.7 | G38: =Parámetros!C30 -> 6 | H38: =E37+158.9-10*LOG10(Parámetros!C13*10^9)-G38 -> 34.1309 | I38: =10^(H38/10) -> 2588.7493 | J38: =10*LOG10(K38) -> 24.037828 | K38: =1/(1/I38+1/K35) -> 253.38608 | L38: =(2/3)^3*Parámetros!C56*(Parámetros!C57)^2*'No linealidades'!D7*(10^(E39/10)*0.001)^2*LOG10(PI()^2*ABS(Parámetros!C58*10^(-24))*'No linealidades'!D7*(Parámetros!C59)^2*Parámetros!C60^2)/(PI()*ABS(Parámetros!C58*10^(-24))*Parámetros!C60^3)*Parámetros!C13*10^9 -> 4.8683036e-05 | M38: =10*LOG10(N38) -> 43.126223 | N38: =1/L38 -> 20541.036 | O38: =10*LOG10(P38) -> 37.142655 | P38: =HARMEAN(N6,N14,N22,N30)/5 -> 5179.2332 | Q38: =10*LOG10(HARMEAN(K38,P38)/2) -> 23.83039
A39: VOA (Booster) | D39: =-(E38-Parámetros!I30) -> -1.2 | E39: =D39+E38 -> 2.5
A40: Fibra | B40: 76 | C40: =Parámetros!C41 -> 0.185 | D40: =-B40*C40 -> -14.06 | E40: =D40+E39 -> -11.56 | F40: =IF(E40>=Parámetros!C18,"V","F") -> V
...

Sheet Enlace Comprometido REG
A1: Benavidez - Rosario | D1: calculos normalizados a 0,1 nm
A2: Presupuesto de Potencia | B2: Distancia (km) | C2: Atenuación por km | D2: Amplificación/Atenuación (dB) | E2: Potencia acumulada (dBm) | F2: 400 Gbps / Limite | G2: NF (dB) | H2: OSNR canal (dB) | I2: OSNR canal (veces) | J2: OSNR acumulada (dB) | K2: OSNR acumulada (veces) | L2: 1/GSNR NL | M2: GSNR NL (dB) | N2: GSNR NL (veces) | O2: GSNR NL acumulada (dB) | P2: GSNR NL acumulada (veces) | Q2: GSNR Total (dB)
A3: Benavidez | F3: 400
A4: Transceiver | E4: =Parámetros!C5 -> -9 | H4: =Parámetros!C9 -> 38 | I4: =10^(H4/10) -> 6309.5734 | J4: =H4 -> 38 | K4: =10^(J4/10) -> 6309.5734 | L4: - | M4: - | N4: - | O4: - | P4: -
A5: MUX+ | D5: =-Parámetros!C16 -> -10 | E5: =D5+E4 -> -19 | F5: =Parámetros!C29 -> -17.52
A6: Amplificador Booster | D6: =Parámetros!C27 -> 21.5 | E6: =D6+E5 -> 2.5 | G6: =Parámetros!C30 -> 6 | H6: =E5+158.9-10*LOG10(Parámetros!C13*10^9)-G6 -> 32.9309 | I6: =10^(H6/10) -> 1963.7671 | J6: =10*LOG10(K6) -> 31.754091 | K6: =1/((1/K4)+(1/I6)) -> 1497.6457 | L6: =(2/3)^3*Parámetros!C56*(Parámetros!C57)^2*'No linealidades'!D3*(10^(E7/10)*0.001)^2*LOG10(PI()^2*ABS(Parámetros!C58*10^(-24))*'No linealidades'!D3*(Parámetros!C59)^2*Parámetros!C60^2)/(PI()*ABS(Parámetros!C58*10^(-24))*Parámetros!C60^3)*Parámetros!C13*10^9 -> 4.9024839e-05 | M6: =10*LOG10(N6) -> 43.095838 | N6: =1/L6 -> 20397.823 | O6: =M6 -> 43.095838 | P6: =N6 -> 20397.823 | Q6: =10*LOG10(HARMEAN(K6,P6)/2) -> 31.446387
A7: VOA (Booster) | D7: 0 | E7: =D7+E6 -> 2.5
A8: Fibra | B8: 80 | C8: =Parámetros!C41 -> 0.185 | D8: =-B8*C8 -> -14.8 | E8: =D8+E7 -> -12.3 | F8: =IF(E8>=Parámetros!C18,"V","F") -> V
A9: Campana
A10: VOA (Line In) | D10: =-(E8+Parámetros!H18) -> -6.5 | E10: =E8+D10 -> -18.8 | F10: =Parámetros!C22 -> -18.02
A11: Preamplificador | D11: =Parámetros!C20 -> 21 | E11: =D11+E10 -> 2.2 | G11: =Parámetros!C23 -> 5.5 | H11: =E10+158.9-10*LOG10(Parámetros!C13*10^9)-G11 -> 33.6309 | I11: =10^(H11/10) -> 2307.2252 | J11: =10*LOG10(K11) -> 29.581591 | K11: =1/(1/I11+1/K6) -> 908.15326 | L11: - | M11: - | N11: - | O11: - | P11: - | Q11: =10*LOG10(HARMEAN(K11,P6)/2) -> 29.392415
A12: WSS+ (ROADM 1) | D12: =-Parámetros!C16 -> -10 | E12: =D12+E11 -> -7.8
A13: WSS+ (ROADM 2) | D13: =-Parámetros!C16 -> -10 | E13: =D13+E12 -> -17.8 | F13: =Parámetros!C29 -> -17.52
A14: Amplificador Booster | D14: =Parámetros!C27 -> 21.5 | E14: =D14+E13 -> 3.7 | G14: =Parámetros!C30 -> 6 | H14: =E13+158.9-10*LOG10(Parámetros!C13*10^9)-G14 -> 34.1309 | I14: =10^(H14/10) -> 2588.7493 | J14: =10*LOG10(K14) -> 28.275656 | K14: =1/(1/I14+1/K11) -> 672.30386 | L14: =(2/3)^3*Parámetros!C56*(Parámetros!C57)^2*'No linealidades'!D4*(10^(E15/10)*0.001)^2*LOG10(PI()^2*ABS(Parámetros!C58*10^(-24))*'No linealidades'!D4*(Parámetros!C59)^2*Parámetros!C60^2)/(PI()*ABS(Parámetros!C58*10^(-24))*Parámetros!C60^3)*Parámetros!C13*10^9 -> 1.9856792e-05 | M14: =10*LOG10(N14) -> 47.020909 | N14: =1/L14 -> 50360.603 | O14: =10*LOG10(P14) -> 41.618966 | P14: =HARMEAN(N6,N14)/2 -> 14517.659 | Q14: =10*LOG10(HARMEAN(K14,P14)/2) -> 28.079055
A15: VOA (Booster) | D15: =-(E14-Parámetros!I30) -> -1.2 | E15: =D15+E14 -> 2.5
A16: Fibra | B16: 13 | C16: =Parámetros!C41 -> 0.185 | D16: =-B16*C16 -> -2.405 | E16: =D16+E15 -> 0.095 | F16: =IF(E16>=Parámetros!C18,"V","F") -> V
A17: Zarate
A18: VOA (Line In) | D18: =-(E16+Parámetros!H18) -> -18.895 | E18: =E16+D18 -> -18.8 | F18: =Parámetros!C22 -> -18.02
A19: Preamplificador | D19: =Parámetros!C20 -> 21 | E19: =D19+E18 -> 2.2 | G19: =Parámetros!C23 -> 5.5 | H19: =E18+158.9-10*LOG10(Parámetros!C13*10^9)-G19 -> 33.6309 | I19: =10^(H19/10) -> 2307.2252 | J19: =10*LOG10(K19) -> 27.16508 | K19: =1/(1/I19+1/K14) -> 520.60456 | L19: - | M19: - | N19: - | O19: - | P19: - | Q19: =10*LOG10(HARMEAN(K19,P14)/2) -> 27.012069
A20: WSS+ (ROADM 1) | D20: =-Parámetros!C16 -> -10 | E20: =D20+E19 -> -7.8
A21: WSS+ (ROADM 2) | D21: =-Parámetros!C16 -> -10 | E21: =D21+E20 -> -17.8 | F21: =Parámetros!C29 -> -17.52
A22: Amplificador Booster | D22: =Parámetros!C27 -> 21.5 | E22: =D22+E21 -> 3.7 | G22: =Parámetros!C30 -> 6 | H22: =E21+158.9-10*LOG10(Parámetros!C13*10^9)-G22 -> 34.1309 | I22: =10^(H22/10) -> 2588.7493 | J22: =10*LOG10(K22) -> 26.369278 | K22: =1/(1/I22+1/K19) -> 433.43883 | L22: =(2/3)^3*Parámetros!C56*(Parámetros!C57)^2*'No linealidades'!D5*(10^(E23/10)*0.001)^2*LOG10(PI()^2*ABS(Parámetros!C58*10^(-24))*'No linealidades'!D5*(Parámetros!C59)^2*Parámetros!C60^2)/(PI()*ABS(Parámetros!C58*10^(-24))*Parámetros!C60^3)*Parámetros!C13*10^9 -> 4.7664792e-05 | M22: =10*LOG10(N22) -> 43.218023 | N22: =1/L22 -> 20979.846 | O22: =10*LOG10(P22) -> 39.335011 | P22: =HARMEAN(N6,N14,N22)/3 -> 8580.2719 | Q22: =10*LOG10(HARMEAN(K22,P22)/2) -> 26.155252
A23: VOA (Booster) | D23: =-(E22-Parámetros!I30) -> -1.2 | E23: =D23+E22 -> 2.5
A24: Fibra | B24: 67 | C24: =Parámetros!C41 -> 0.185 | D24: =-B24*C24 -> -12.395 | E24: =D24+E23 -> -9.895 | F24: =IF(E24>=Parámetros!C18,"V","F") -> V
A25: Baradero
A26: VOA (Line In) | D26: =-(E24+Parámetros!H18) -> -8.905 | E26: =E24+D26 -> -18.8 | F26: =Parámetros!C22 -> -18.02
A27: Preamplificador | D27: =Parámetros!C20 -> 21 | E27: =D27+E26 -> 2.2 | G27: =Parámetros!C23 -> 5.5 | H27: =E26+158.9-10*LOG10(Parámetros!C13*10^9)-G27 -> 33.6309 | I27: =10^(H27/10) -> 2307.2252 | J27: =10*LOG10(K27) -> 25.62162 | K27: =1/(1/I27+1/K22) -> 364.89003 | L27: - | M27: - | N27: - | O27: - | P27: - | Q27: =10*LOG10(HARMEAN(K27,P22)/2) -> 25.440748
A28: WSS+ (ROADM 1) | D28: =-Parámetros!C16 -> -10 | E28: =D28+E27 -> -7.8
A29: WSS+ (ROADM 2) | D29: =-Parámetros!C16 -> -10 | E29: =D29+E28 -> -17.8 | F29: =Parámetros!C29 -> -17.52
A30: Amplificador Booster | D30: =Parámetros!C27 -> 21.5 | E30: =D30+E29 -> 3.7 | G30: =Parámetros!C30 -> 6 | H30: =E29+158.9-10*LOG10(Parámetros!C13*10^9)-G30 -> 34.1309 | I30: =10^(H30/10) -> 2588.7493 | J30: =10*LOG10(K30) -> 25.048945 | K30: =1/(1/I30+1/K27) -> 319.81183 | L30: =(2/3)^3*Parámetros!C56*(Parámetros!C57)^2*'No linealidades'!D6*(10^(E31/10)*0.001)^2*LOG10(PI()^2*ABS(Parámetros!C58*10^(-24))*'No linealidades'!D6*(Parámetros!C59)^2*Parámetros!C60^2)/(PI()*ABS(Parámetros!C58*10^(-24))*Parámetros!C60^3)*Parámetros!C13*10^9 -> 3.7916598e-05 | M30: =10*LOG10(N30) -> 44.211706 | N30: =1/L30 -> 26373.674 | O30: =10*LOG10(P30) -> 38.111755 | P30: =HARMEAN(N6,N14,N22,N30)/4 -> 6474.0415 | Q30: =10*LOG10(HARMEAN(K30,P30)/2) -> 24.839538
A31: VOA (Booster) | D31: =-(E30-Parámetros!I30) -> -1.2 | E31: =D31+E30 -> 2.5
A32: Fibra | B32: 34 | C32: =Parámetros!C41 -> 0.185 | D32: =-B32*C32 -> -6.29 | E32: =D32+E31 -> -3.79 | F32: =IF(E32>=Parámetros!C18,"V","F") -> V
A33: San Pedro BsAs (Regeneracion)
A34: VOA (Line In) | D34: =-(E32+Parámetros!H18) -> -15.01 | E34: =D34+E32 -> -18.8 | F34: =Parámetros!C22 -> -18.02
A35: Preamplificador | D35: =Parámetros!C20 -> 21 | E35: =D35+E34 -> 2.2 | G35: =Parámetros!C23 -> 5.5 | H35: =E34+158.9-10*LOG10(Parámetros!C13*10^9)-G35 -> 33.6309 | I35: =10^(H35/10) -> 2307.2252 | J35: =10*LOG10(K35) -> 24.485183 | K35: =1/(1/I35+1/K30) -> 280.87839 | L35: - | M35: - | N35: - | O35: - | P35: - | Q35: =10*LOG10(HARMEAN(K35,P30)/2) -> 24.300736
A36: DEMUX+ | D36: =-Parámetros!C16 -> -10 | E36: =D36+E35 -> -7.8
A37: Transceiver (Rx) | E37: =E36 -> -7.8
A38: Transceiver (Tx) | E38: =Parámetros!C5 -> -9 | H38: =Parámetros!C9 -> 38 | I38: =10^(H38/10) -> 6309.5734 | J38: =H38 -> 38 | K38: =10^(J38/10) -> 6309.5734 | L38: - | M38: - | N38: - | O38: - | P38: -
A39: MUX+ | D39: =-Parámetros!C16 -> -10 | E39: =D39+E38 -> -19 | F39: =Parámetros!C29 -> -17.52
A40: Amplificador Booster | D40: =Parámetros!C27 -> 21.5 | E40: =D40+E39 -> 2.5 | G40: =Parámetros!C30 -> 6 | H40: =E39+158.9-10*LOG10(Parámetros!C13*10^9)-G40 -> 32.9309 | I40: =10^(H40/10) -> 1963.7671 | J40: =10*LOG10(K40) -> 31.754091 | K40: =1/((1/K38)+(1/I40)) -> 1497.6457 | L40: =(2/3)^3*Parámetros!C56*(Parámetros!C57)^2*'No linealidades'!D7*(10^(E41/10)*0.001)^2*LOG10(PI()^2*ABS(Parámetros!C58*10^(-24))*'No linealidades'!D7*(Parámetros!C59)^2*Parámetros!C60^2)/(PI()*ABS(Parámetros!C58*10^(-24))*Parámetros!C60^3)*Parámetros!C13*10^9 -> 4.8683036e-05 | M40: =10*LOG10(N40) -> 43.126223 | N40: =1/L40 -> 20541.036 | O40: =10*LOG10(P40) -> 43.126223 | P40: =N40 -> 20541.036 | Q40: =10*LOG10(HARMEAN(K40,P40)/2) -> 31.448458
...

Sheet No linealidades
A1: No Linealidades (COMPROMETIDO)
A2: Tramo | B2: Distancia (km) | C2: Potencia de entrada a la fibra (dBm) | D2: Longitud Efectiva (km) | E2: Longitud No Lineal (km)
A3: Benavidez-Campana | B3: 80 | C3: ='Enlace Comprometido'!E7 -> 2.5 | D3: =(1-EXP(-$H$3*B3))/$H$3 -> 22.698035 | E3: =(1.55*Parámetros!$C$46)/(2*PI()*Parámetros!$C$47*10^(C3/10)*0.001)*10^-9 -> 655.0859 | G3: α (dB/km) | H3: =Parámetros!$C$41*LN(10)/10 -> 0.042597824
A4: Campana-Zarate | B4: 13 | C4: ='Enlace Comprometido'!E15 -> 2.5 | D4: =(1-EXP(-$H$3*B4))/$H$3 -> 9.9822512 | E4: =(1.55*Parámetros!$C$46)/(2*PI()*Parámetros!$C$47*10^(C4/10)*0.001)*10^-9 -> 655.0859
A5: Zarate-Baradero | B5: 67 | C5: ='Enlace Comprometido'!E23 -> 2.5 | D5: =(1-EXP(-$H$3*B5))/$H$3 -> 22.122954 | E5: =(1.55*Parámetros!$C$46)/(2*PI()*Parámetros!$C$47*10^(C5/10)*0.001)*10^-9 -> 655.0859
A6: Baradero-San Pedro BsAs | B6: 34 | C6: ='Enlace Comprometido'!E31 -> 2.5 | D6: =(1-EXP(-$H$3*B6))/$H$3 -> 17.959526 | E6: =(1.55*Parámetros!$C$46)/(2*PI()*Parámetros!$C$47*10^(C6/10)*0.001)*10^-9 -> 655.0859
A7: San Pedro BsAs-San Nicolas | B7: 76 | C7: ='Enlace Comprometido'!E39 -> 2.5 | D7: =(1-EXP(-$H$3*B7))/$H$3 -> 22.553629 | E7: =(1.55*Parámetros!$C$46)/(2*PI()*Parámetros!$C$47*10^(C7/10)*0.001)*10^-9 -> 655.0859
A8: San Nicolas-Rosario | B8: 81 | C8: ='Enlace Comprometido'!E47 -> 2.5 | D8: =(1-EXP(-$H$3*B8))/$H$3 -> 22.730452 | E8: =(1.55*Parámetros!$C$46)/(2*PI()*Parámetros!$C$47*10^(C8/10)*0.001)*10^-9 -> 655.0859
A9: TOTAL | B9: =SUM(B3:B8) -> 351
A11: No Linealidades (LARGO)
A12: Tramo | B12: Distancia (km) | C12: Potencia de entrada a la fibra (dBm) | D12: Longitud Efectiva (km) | E12: Longitud No Lineal (km)
A13: DinaHuapi-Comallo | B13: 107 | C13: ='Enlace Largo 100Gbps'!E7 -> 2.5 | D13: =(1-EXP(-$H$3*B13))/$H$3 -> 23.229277 | E13: =(1.55*Parámetros!$C$46)/(2*PI()*Parámetros!$C$47*10^(C13/10)*0.001)*10^-9 -> 655.0859
A14: Comallo-IngJacobacci | B14: 95 | C14: ='Enlace Largo 100Gbps'!E11 -> 5.48 | D14: =(1-EXP(-$H$3*B14))/$H$3 -> 23.065067 | E14: =(1.55*Parámetros!$C$46)/(2*PI()*Parámetros!$C$47*10^(C14/10)*0.001)*10^-9 -> 329.83615
A15: IngJacobacci-Maquinchao | B15: 77 | C15: ='Enlace Largo 100Gbps'!E15 -> 5.48 | D15: =(1-EXP(-$H$3*B15))/$H$3 -> 22.592069 | E15: =(1.55*Parámetros!$C$46)/(2*PI()*Parámetros!$C$47*10^(C15/10)*0.001)*10^-9 -> 329.83615
A16: Maquinchao-LosMenucos | B16: 74 | C16: ='Enlace Largo 100Gbps'!E19 -> 5.48 | D16: =(1-EXP(-$H$3*B16))/$H$3 -> 22.471657 | E16: =(1.55*Parámetros!$C$46)/(2*PI()*Parámetros!$C$47*10^(C16/10)*0.001)*10^-9 -> 329.83615
A17: LosMenucos-MinistroRamosMexia | B17: 96 | C17: ='Enlace Largo 100Gbps'!E23 -> 5.48 | D17: =(1-EXP(-$H$3*B17))/$H$3 -> 23.082178 | E17: =(1.55*Parámetros!$C$46)/(2*PI()*Parámetros!$C$47*10^(C17/10)*0.001)*10^-9 -> 329.83615
A18: MinistroRamosMexia-NahuelNiyeu | B18: 64 | C18: ='Enlace Largo 100Gbps'!E27 -> 5.48 | D18: =(1-EXP(-$H$3*B18))/$H$3 -> 21.938594 | E18: =(1.55*Parámetros!$C$46)/(2*PI()*Parámetros!$C$47*10^(C18/10)*0.001)*10^-9 -> 329.83615
A19: NahuelNiyeu-AguadaCecilio | B19: 79 | C19: ='Enlace Largo 100Gbps'!E31 -> 5.48 | D19: =(1-EXP(-$H$3*B19))/$H$3 -> 22.664206 | E19: =(1.55*Parámetros!$C$46)/(2*PI()*Parámetros!$C$47*10^(C19/10)*0.001)*10^-9 -> 329.83615
A20: TOTAL | B20: =SUM(B13:B19) -> 592

Sheet Enlace Largo 100Gbps
A1: Dina Huapi - Aguada Cecilio | D1: calculos normalizados a 0,1 nm
A2: Presupuesto de Potencia | B2: Distancia (km) | C2: Atenuación por km | D2: Amplificación/Atenuación (dB) | E2: Potencia acumulada (dBm) | F2: 100 Gbps / Limite | G2: NF (dB) | H2: OSNR canal (dB) | I2: OSNR canal (veces) | J2: OSNR acumulada (dB) | K2: OSNR acumulada (veces) | L2: 1/GSNR NL | M2: GSNR NL (dB) | N2: GSNR NL (veces) | O2: GSNR NL acumulada (dB) | P2: GSNR NL acumulada (veces) | Q2: GSNR Total (dB)
A3: Dina Huapi | F3: 100
A4: Transceiver | E4: =Parámetros!C65 -> -9 | H4: =Parámetros!C9 -> 38 | I4: =10^(H4/10) -> 6309.5734 | J4: =H4 -> 38 | K4: =I4 -> 6309.5734 | L4: - | M4: - | N4: - | O4: - | P4: -
A5: MUX+ | D5: =-Parámetros!C16 -> -10 | E5: =D5+E4 -> -19 | F5: =Parámetros!C$29 -> -17.52
A6: Amplificador Booster | D6: =Parámetros!C27 -> 21.5 | E6: =D6+E5 -> 2.5 | G6: =Parámetros!C30 -> 6 | H6: =E5+158.9-10*LOG10(Parámetros!C13*10^9)-G6 -> 32.9309 | I6: =10^(H6/10) -> 1963.7671 | J6: =10*LOG10(K6) -> 31.754091 | K6: =1/((1/K4)+(1/I6)) -> 1497.6457 | L6: =(2/3)^3*Parámetros!C56*(Parámetros!C57)^2*'No linealidades'!D13*(10^(E7/10)*0.001)^2*LOG10(PI()^2*ABS(Parámetros!C58*10^(-24))*'No linealidades'!D13*(Parámetros!C59)^2*Parámetros!C74^2)/(PI()*ABS(Parámetros!C58*10^(-24))*Parámetros!C74^3)*Parámetros!C73*10^9 -> 0.00034721887 | M6: =10*LOG10(N6) -> 34.593967 | N6: =1/L6 -> 2880.0278 | O6: =M6 -> 34.593967 | P6: =N6 -> 2880.0278 | Q6: =10*LOG10(HARMEAN(K6,P6)/2) -> 29.935624
A7: VOA (BOOSTER) | D7: 0 | E7: =E6 -> 2.5
A8: Fibra | B8: 107 | C8: =Parámetros!C41 -> 0.185 | D8: =-B8*C8 -> -19.795 | E8: =D8+E7 -> -17.295 | F8: =IF(E8>=Parámetros!C$33,"V","F") -> V
A9: Comallo
A10: VOA (ILA) | D10: =-(E8-Parámetros!C$37) -> -2.225 | E10: =E8+D10 -> -19.52 | F10: =Parámetros!C$37 -> -19.52
A11: Amplificador (Comallo) | D11: =Parámetros!C$35 -> 25 | E11: =E10+D11 -> 5.48 | G11: =Parámetros!C$38 -> 5.5 | H11: =E10+158.9-10*LOG10(Parámetros!C$13*10^9)-G11 -> 32.9109 | I11: =10^(H11/10) -> 1954.7444 | J11: =10*LOG10(K11) -> 29.283792 | K11: =1/((1/K6)+(1/I11)) -> 847.96749 | L11: =(2/3)^3*Parámetros!C56*(Parámetros!C57)^2*'No linealidades'!D14*(10^(E11/10)*0.001)^2*LOG10(PI()^2*ABS(Parámetros!C58*10^(-24))*'No linealidades'!D14*(Parámetros!C59)^2*Parámetros!C74^2)/(PI()*ABS(Parámetros!C58*10^(-24))*Parámetros!C74^3)*Parámetros!C73*10^9 -> 0.0013588805 | M11: =10*LOG10(N11) -> 28.668187 | N11: =1/L11 -> 735.89989 | O11: =10*LOG10(P11) -> 27.679957 | P11: =HARMEAN(N11,N6)/2 -> 586.13233 | Q11: =10*LOG10(HARMEAN(K11,P11)/2) -> 25.397955
A12: Fibra | B12: 95 | C12: =Parámetros!C41 -> 0.185 | D12: =-B12*C12 -> -17.575 | E12: =D12+E11 -> -12.095 | F12: =IF(E12>=Parámetros!C$33,"V","F") -> V
A13: Ing. Jacobacci
A14: VOA (ILA) | D14: =-(E12-Parámetros!C$37) -> -7.425 | E14: =D14+E12 -> -19.52 | F14: =Parámetros!C$37 -> -19.52
A15: Amplificador (Ing. Jacobacci) | D15: =Parámetros!C$35 -> 25 | E15: =D15+E14 -> 5.48 | G15: =Parámetros!C$38 -> 5.5 | H15: =E14+158.9-10*LOG10(Parámetros!C$13*10^9)-G15 -> 32.9109 | I15: =10^(H15/10) -> 1954.7444 | J15: =10*LOG10(K15) -> 27.718907 | K15: =1/((1/K11)+(1/I15)) -> 591.41281 | L15: =(2/3)^3*Parámetros!C56*(Parámetros!C57)^2*'No linealidades'!D15*(10^(E15/10)*0.001)^2*LOG10(PI()^2*ABS(Parámetros!C58*10^(-24))*'No linealidades'!D15*(Parámetros!C59)^2*Parámetros!C74^2)/(PI()*ABS(Parámetros!C58*10^(-24))*Parámetros!C74^3)*Parámetros!C73*10^9 -> 0.0013279594 | M15: =10*LOG10(N15) -> 28.768152 | N15: =1/L15 -> 753.03509 | O15: =10*LOG10(P15) -> 25.17976 | P15: =HARMEAN(N11,N6,N15)/3 -> 329.59151 | Q15: =10*LOG10(HARMEAN(K15,P15)/2) -> 23.256051
A16: Fibra | B16: 77 | C16: =Parámetros!C41 -> 0.185 | D16: =-B16*C16 -> -14.245 | E16: =D16+E15 -> -8.765 | F16: =IF(E16>=Parámetros!C$33,"V","F") -> V
A17: Maquinchao
A18: VOA (ILA) | D18: =-(E16-Parámetros!C$37) -> -10.755 | E18: =D18+E16 -> -19.52 | F18: =Parámetros!C$37 -> -19.52
A19: Amplificador (Maquinchao) | D19: =Parámetros!C$35 -> 25 | E19: =D19+E18 -> 5.48 | G19: =Parámetros!C$38 -> 5.5 | H19: =E18+158.9-10*LOG10(Parámetros!C$13*10^9)-G19 -> 32.9109 | I19: =10^(H19/10) -> 1954.7444 | J19: =10*LOG10(K19) -> 26.570955 | K19: =1/((1/K15)+(1/I19)) -> 454.04144 | L19: =(2/3)^3*Parámetros!C56*(Parámetros!C57)^2*'No linealidades'!D16*(10^(E19/10)*0.001)^2*LOG10(PI()^2*ABS(Parámetros!C58*10^(-24))*'No linealidades'!D16*(Parámetros!C59)^2*Parámetros!C74^2)/(PI()*ABS(Parámetros!C58*10^(-24))*Parámetros!C74^3)*Parámetros!C73*10^9 -> 0.001320098 | M19: =10*LOG10(N19) -> 28.793938 | N19: =1/L19 -> 757.5195 | O19: =10*LOG10(P19) -> 23.610959 | P19: =HARMEAN(N11,N6,N15,N19)/4 -> 229.66559 | Q19: =10*LOG10(HARMEAN(K19,P19)/2) -> 21.833214
A20: Fibra | B20: 74 | C20: =Parámetros!C41 -> 0.185 | D20: =-B20*C20 -> -13.69 | E20: =D20+E19 -> -8.21 | F20: =IF(E20>=Parámetros!C$33,"V","F") -> V
A21: Los Menucos
A22: VOA (ILA) | D22: =-(E20-Parámetros!C$37) -> -11.31 | E22: =D22+E20 -> -19.52 | F22: =Parámetros!C$37 -> -19.52
A23: Amplificador (Los Menucos) | D23: =Parámetros!C$35 -> 25 | E23: =D23+E22 -> 5.48 | G23: =Parámetros!C$38 -> 5.5 | H23: =E22+158.9-10*LOG10(Parámetros!C$13*10^9)-G23 -> 32.9109 | I23: =10^(H23/10) -> 1954.7444 | J23: =10*LOG10(K23) -> 25.663873 | K23: =1/((1/K19)+(1/I23)) -> 368.4574 | L23: =(2/3)^3*Parámetros!C56*(Parámetros!C57)^2*'No linealidades'!D17*(10^(E23/10)*0.001)^2*LOG10(PI()^2*ABS(Parámetros!C58*10^(-24))*'No linealidades'!D17*(Parámetros!C59)^2*Parámetros!C74^2)/(PI()*ABS(Parámetros!C58*10^(-24))*Parámetros!C74^3)*Parámetros!C73*10^9 -> 0.0013600003 | M23: =10*LOG10(N23) -> 28.66461 | N23: =1/L23 -> 735.29396 | O23: =10*LOG10(P23) -> 22.430478 | P23: =HARMEAN(N11,N6,N15,N19,N23)/5 -> 175.00394 | Q23: =10*LOG10(HARMEAN(K23,P23)/2) -> 20.742665
A24: Fibra | B24: 96 | C24: =Parámetros!C41 -> 0.185 | D24: =-B24*C24 -> -17.76 | E24: =D24+E23 -> -12.28 | F24: =IF(E24>=Parámetros!C$33,"V","F") -> V
A25: Ministro Ramos Mexía
A26: VOA (ILA) | D26: =-(E24-Parámetros!C$37) -> -7.24 | E26: =D26+E24 -> -19.52 | F26: =Parámetros!C$37 -> -19.52
A27: Amplificador (Ministro Ramos Mexía) | D27: =Parámetros!C$35 -> 25 | E27: =D27+E26 -> 5.48 | G27: =Parámetros!C$38 -> 5.5 | H27: =E26+158.9-10*LOG10(Parámetros!C$13*10^9)-G27 -> 32.9109 | I27: =10^(H27/10) -> 1954.7444 | J27: =10*LOG10(K27) -> 24.913903 | K27: =1/((1/K23)+(1/I27)) -> 310.02044 | L27: =(2/3)^3*Parámetros!C56*(Parámetros!C57)^2*'No linealidades'!D18*(10^(E27/10)*0.001)^2*LOG10(PI()^2*ABS(Parámetros!C58*10^(-24))*'No linealidades'!D18*(Parámetros!C59)^2*Parámetros!C74^2)/(PI()*ABS(Parámetros!C58*10^(-24))*Parámetros!C74^3)*Parámetros!C73*10^9 -> 0.0012853467 | M27: =10*LOG10(N27) -> 28.909797 | N27: =1/L27 -> 778.00024 | O27: =10*LOG10(P27) -> 21.549328 | P27: =HARMEAN(N11,N6,N15,N19,N23,N27)/6 -> 142.86727 | Q27: =10*LOG10(HARMEAN(K27,P27)/2) -> 19.903325
A28: Fibra | B28: 64 | C28: =Parámetros!C41 -> 0.185 | D28: =-B28*C28 -> -11.84 | E28: =D28+E27 -> -6.36 | F28: =IF(E28>=Parámetros!C$33,"V","F") -> V
A29: Nahuel Niyeu
A30: VOA (ILA) | D30: =-(E28-Parámetros!C$37) -> -13.16 | E30: =D30+E28 -> -19.52 | F30: =Parámetros!C$37 -> -19.52
A31: Amplificador (Nahuel Niyeu) | D31: =Parámetros!C$35 -> 25 | E31: =D31+E30 -> 5.48 | G31: =Parámetros!C$38 -> 5.5 | H31: =E30+158.9-10*LOG10(Parámetros!C$13*10^9)-G31 -> 32.9109 | I31: =10^(H31/10) -> 1954.7444 | J31: =10*LOG10(K31) -> 24.274572 | K31: =1/((1/K27)+(1/I31)) -> 267.58218 | L31: =(2/3)^3*Parámetros!C56*(Parámetros!C57)^2*'No linealidades'!D19*(10^(E31/10)*0.001)^2*LOG10(PI()^2*ABS(Parámetros!C58*10^(-24))*'No linealidades'!D19*(Parámetros!C59)^2*Parámetros!C74^2)/(PI()*ABS(Parámetros!C58*10^(-24))*Parámetros!C74^3)*Parámetros!C73*10^9 -> 0.001332671 | M31: =10*LOG10(N31) -> 28.75277 | N31: =1/L31 -> 750.37273 | O31: =10*LOG10(P31) -> 20.792416 | P31: =HARMEAN(N11,N6,N15,N19,N23,N27,N31)/7 -> 120.01669 | Q31: =10*LOG10(HARMEAN(K31,P31)/2) -> 19.183163
A32: Fibra | B32: 79 | C32: =Parámetros!C41 -> 0.185 | D32: =-B32*C32 -> -14.615 | E32: =D32+E31 -> -9.135 | F32: =IF(E32>=Parámetros!C$33,"V","F") -> V
A33: Aguada Cecilio
A34: VOA (Line In) | D34: =-(E32+Parámetros!H18) -> -9.665 | E34: =D34+E32 -> -18.8 | F34: =Parámetros!C22 -> -18.02
A35: Preamplificador | D35: =Parámetros!C20 -> 21 | E35: =D35+E34 -> 2.2 | G35: =Parámetros!C23 -> 5.5 | H35: =E34+158.9-10*LOG10(Parámetros!C$13*10^9)-G35 -> 33.6309 | I35: =10^(H35/10) -> 2307.2252 | J35: =10*LOG10(K35) -> 23.798024 | K35: =1/((1/K31)+(1/I35)) -> 239.77419 | L35: - | M35: - | N35: - | O35: - | P35: - | Q35: =10*LOG10(HARMEAN(K35,P31)/2) -> 19.029939
A36: DEMUX+ | D36: =-Parámetros!C16 -> -10 | E36: =D36+E35 -> -7.8
A37: Transceiver | E37: =E36 -> -7.8 | F37: =IF(E37>=Parámetros!C67,"V","F") -> V
F38: TOTAL | J38: =J35 -> 23.798024 | K38: =K35 -> 239.77419 | O38: =O31 -> 20.792416 | P38: =P31 -> 120.01669 | Q38: =10*LOG10(HARMEAN(K38,P38)/2) -> 19.029939 | R38: FUNCIONA
F39: Requerido para 100 Gbps | J39: =Parámetros!C70 -> 11.8 | K39: =10^(J39/10) -> 15.135612 | Q39: =Parámetros!C70 -> 11.8
A41: Longitud de onda | B41: Coeficiente DC (ps/(nm.km) | C41: Coeficiente DCF (ps/(nm.km) | D41: Compensacion Transceiver ps/nm | H41: Longitud de onda | I41: Coeficiente DC (ps/(nm.km)
...

Sheet Enlace Largo 200Gbps
A1: Dina Huapi - Aguada Cecilio | D1: calculos normalizados a 0,1 nm
A2: Presupuesto de Potencia | B2: Distancia (km) | C2: Atenuación por km | D2: Amplificación/Atenuación (dB) | E2: Potencia acumulada (dBm) | F2: 200 Gbps / Limite | G2: NF (dB) | H2: OSNR canal (dB) | I2: OSNR canal (veces) | J2: OSNR acumulada (dB) | K2: OSNR acumulada (veces) | L2: 1/GSNR NL | M2: GSNR NL (dB) | N2: GSNR NL (veces) | O2: GSNR NL acumulada (dB) | P2: GSNR NL acumulada (veces) | Q2: GSNR Total (dB)
A3: Dina Huapi | F3: 200
A4: Transceiver | E4: =Parámetros!C78 -> -9 | H4: =Parámetros!C82 -> 38 | I4: =10^(H4/10) -> 6309.5734 | J4: =H4 -> 38 | K4: =I4 -> 6309.5734 | L4: - | M4: - | N4: - | O4: - | P4: -
A5: MUX+ | D5: =-Parámetros!C16 -> -10 | E5: =D5+E4 -> -19 | F5: =Parámetros!C$29 -> -17.52
A6: Amplificador Booster | D6: =Parámetros!C27 -> 21.5 | E6: =D6+E5 -> 2.5 | G6: =Parámetros!C30 -> 6 | H6: =E5+158.9-10*LOG10(Parámetros!C13*10^9)-G6 -> 32.9309 | I6: =10^(H6/10) -> 1963.7671 | J6: =10*LOG10(K6) -> 31.754091 | K6: =1/((1/K4)+(1/I6)) -> 1497.6457 | L6: =(2/3)^3*Parámetros!C56*(Parámetros!C57)^2*'No linealidades'!D13*(10^(E7/10)*0.001)^2*LOG10(PI()^2*ABS(Parámetros!C58*10^(-24))*'No linealidades'!D13*(Parámetros!C59)^2*Parámetros!C74^2)/(PI()*ABS(Parámetros!C58*10^(-24))*Parámetros!C74^3)*Parámetros!C73*10^9 -> 0.00034721887 | M6: =10*LOG10(N6) -> 34.593967 | N6: =1/L6 -> 2880.0278 | O6: =M6 -> 34.593967 | P6: =N6 -> 2880.0278 | Q6: =10*LOG10(HARMEAN(K6,P6)/2) -> 29.935624
A7: VOA (BOOSTER) | D7: 0 | E7: =E6 -> 2.5
A8: Fibra | B8: 107 | C8: =Parámetros!C41 -> 0.185 | D8: =-B8*C8 -> -19.795 | E8: =D8+E7 -> -17.295 | F8: =IF(E8>=Parámetros!C$33,"V","F") -> V
A9: Comallo
A10: VOA (ILA) | D10: =-(E8-Parámetros!C$37) -> -2.225 | E10: =E8+D10 -> -19.52 | F10: =Parámetros!C$37 -> -19.52
A11: Amplificador (Comallo) | D11: =Parámetros!C$35 -> 25 | E11: =E10+D11 -> 5.48 | G11: =Parámetros!C$38 -> 5.5 | H11: =E10+158.9-10*LOG10(Parámetros!C$13*10^9)-G11 -> 32.9109 | I11: =10^(H11/10) -> 1954.7444 | J11: =10*LOG10(K11) -> 29.283792 | K11: =1/((1/K6)+(1/I11)) -> 847.96749 | L11: =(2/3)^3*Parámetros!C56*(Parámetros!C57)^2*'No linealidades'!D14*(10^(E11/10)*0.001)^2*LOG10(PI()^2*ABS(Parámetros!C58*10^(-24))*'No linealidades'!D14*(Parámetros!C59)^2*Parámetros!C74^2)/(PI()*ABS(Parámetros!C58*10^(-24))*Parámetros!C74^3)*Parámetros!C73*10^9 -> 0.0013588805 | M11: =10*LOG10(N11) -> 28.668187 | N11: =1/L11 -> 735.89989 | O11: =10*LOG10(P11) -> 27.679957 | P11: =HARMEAN(N11,N6)/2 -> 586.13233 | Q11: =10*LOG10(HARMEAN(K11,P11)/2) -> 25.397955
A12: Fibra | B12: 95 | C12: =Parámetros!C41 -> 0.185 | D12: =-B12*C12 -> -17.575 | E12: =D12+E11 -> -12.095 | F12: =IF(E12>=Parámetros!C$33,"V","F") -> V
A13: Ing. Jacobacci
A14: VOA (ILA) | D14: =-(E12-Parámetros!C$37) -> -7.425 | E14: =D14+E12 -> -19.52 | F14: =Parámetros!C$37 -> -19.52
A15: Amplificador (Ing. Jacobacci) | D15: =Parámetros!C$35 -> 25 | E15: =D15+E14 -> 5.48 | G15: =Parámetros!C$38 -> 5.5 | H15: =E14+158.9-10*LOG10(Parámetros!C$13*10^9)-G15 -> 32.9109 | I15: =10^(H15/10) -> 1954.7444 | J15: =10*LOG10(K15) -> 27.718907 | K15: =1/((1/K11)+(1/I15)) -> 591.41281 | L15: =(2/3)^3*Parámetros!C56*(Parámetros!C57)^2*'No linealidades'!D15*(10^(E15/10)*0.001)^2*LOG10(PI()^2*ABS(Parámetros!C58*10^(-24))*'No linealidades'!D15*(Parámetros!C59)^2*Parámetros!C74^2)/(PI()*ABS(Parámetros!C58*10^(-24))*Parámetros!C74^3)*Parámetros!C73*10^9 -> 0.0013279594 | M15: =10*LOG10(N15) -> 28.768152 | N15: =1/L15 -> 753.03509 | O15: =10*LOG10(P15) -> 25.17976 | P15: =HARMEAN(N11,N6,N15)/3 -> 329.59151 | Q15: =10*LOG10(HARMEAN(K15,P15)/2) -> 23.256051
A16: Fibra | B16: 77 | C16: =Parámetros!C41 -> 0.185 | D16: =-B16*C16 -> -14.245 | E16: =D16+E15 -> -8.765 | F16: =IF(E16>=Parámetros!C$33,"V","F") -> V
A17: Maquinchao
A18: VOA (ILA) | D18: =-(E16-Parámetros!C$37) -> -10.755 | E18: =D18+E16 -> -19.52 | F18: =Parámetros!C$37 -> -19.52
A19: Amplificador (Maquinchao) | D19: =Parámetros!C$35 -> 25 | E19: =D19+E18 -> 5.48 | G19: =Parámetros!C$38 -> 5.5 | H19: =E18+158.9-10*LOG10(Parámetros!C$13*10^9)-G19 -> 32.9109 | I19: =10^(H19/10) -> 1954.7444 | J19: =10*LOG10(K19) -> 26.570955 | K19: =1/((1/K15)+(1/I19)) -> 454.04144 | L19: =(2/3)^3*Parámetros!C56*(Parámetros!C57)^2*'No linealidades'!D16*(10^(E19/10)*0.001)^2*LOG10(PI()^2*ABS(Parámetros!C58*10^(-24))*'No linealidades'!D16*(Parámetros!C59)^2*Parámetros!C74^2)/(PI()*ABS(Parámetros!C58*10^(-24))*Parámetros!C74^3)*Parámetros!C73*10^9 -> 0.001320098 | M19: =10*LOG10(N19) -> 28.793938 | N19: =1/L19 -> 757.5195 | O19: =10*LOG10(P19) -> 23.610959 | P19: =HARMEAN(N11,N6,N15,N19)/4 -> 229.66559 | Q19: =10*LOG10(HARMEAN(K19,P19)/2) -> 21.833214
A20: Fibra | B20: 74 | C20: =Parámetros!C41 -> 0.185 | D20: =-B20*C20 -> -13.69 | E20: =D20+E19 -> -8.21 | F20: =IF(E20>=Parámetros!C$33,"V","F") -> V
A21: Los Menucos
A22: VOA (ILA) | D22: =-(E20-Parámetros!C$37) -> -11.31 | E22: =D22+E20 -> -19.52 | F22: =Parámetros!C$37 -> -19.52
A23: Amplificador (Los Menucos) | D23: =Parámetros!C$35 -> 25 | E23: =D23+E22 -> 5.48 | G23: =Parámetros!C$38 -> 5.5 | H23: =E22+158.9-10*LOG10(Parámetros!C$13*10^9)-G23 -> 32.9109 | I23: =10^(H23/10) -> 1954.7444 | J23: =10*LOG10(K23) -> 25.663873 | K23: =1/((1/K19)+(1/I23)) -> 368.4574 | L23: =(2/3)^3*Parámetros!C56*(Parámetros!C57)^2*'No linealidades'!D17*(10^(E23/10)*0.001)^2*LOG10(PI()^2*ABS(Parámetros!C58*10^(-24))*'No linealidades'!D17*(Parámetros!C59)^2*Parámetros!C74^2)/(PI()*ABS(Parámetros!C58*10^(-24))*Parámetros!C74^3)*Parámetros!C73*10^9 -> 0.0013600003 | M23: =10*LOG10(N23) -> 28.66461 | N23: =1/L23 -> 735.29396 | O23: =10*LOG10(P23) -> 22.430478 | P23: =HARMEAN(N11,N6,N15,N19,N23)/5 -> 175.00394 | Q23: =10*LOG10(HARMEAN(K23,P23)/2) -> 20.742665
A24: Fibra | B24: 96 | C24: =Parámetros!C41 -> 0.185 | D24: =-B24*C24 -> -17.76 | E24: =D24+E23 -> -12.28 | F24: =IF(E24>=Parámetros!C$33,"V","F") -> V
A25: Ministro Ramos Mexía
A26: VOA (ILA) | D26: =-(E24-Parámetros!C$37) -> -7.24 | E26: =D26+E24 -> -19.52 | F26: =Parámetros!C$37 -> -19.52
A27: Amplificador (Ministro Ramos Mexía) | D27: =Parámetros!C$35 -> 25 | E27: =D27+E26 -> 5.48 | G27: =Parámetros!C$38 -> 5.5 | H27: =E26+158.9-10*LOG10(Parámetros!C$13*10^9)-G27 -> 32.9109 | I27: =10^(H27/10) -> 1954.7444 | J27: =10*LOG10(K27) -> 24.913903 | K27: =1/((1/K23)+(1/I27)) -> 310.02044 | L27: =(2/3)^3*Parámetros!C56*(Parámetros!C57)^2*'No linealidades'!D18*(10^(E27/10)*0.001)^2*LOG10(PI()^2*ABS(Parámetros!C58*10^(-24))*'No linealidades'!D18*(Parámetros!C59)^2*Parámetros!C74^2)/(PI()*ABS(Parámetros!C58*10^(-24))*Parámetros!C74^3)*Parámetros!C73*10^9 -> 0.0012853467 | M27: =10*LOG10(N27) -> 28.909797 | N27: =1/L27 -> 778.00024 | O27: =10*LOG10(P27) -> 21.549328 | P27: =HARMEAN(N11,N6,N15,N19,N23,N27)/6 -> 142.86727 | Q27: =10*LOG10(HARMEAN(K27,P27)/2) -> 19.903325
A28: Fibra | B28: 64 | C28: =Parámetros!C41 -> 0.185 | D28: =-B28*C28 -> -11.84 | E28: =D28+E27 -> -6.36 | F28: =IF(E28>=Parámetros!C$33,"V","F") -> V
A29: Nahuel Niyeu
A30: VOA (ILA) | D30: =-(E28-Parámetros!C$37) -> -13.16 | E30: =D30+E28 -> -19.52 | F30: =Parámetros!C$37 -> -19.52
A31: Amplificador (Nahuel Niyeu) | D31: =Parámetros!C$35 -> 25 | E31: =D31+E30 -> 5.48 | G31: =Parámetros!C$38 -> 5.5 | H31: =E30+158.9-10*LOG10(Parámetros!C$13*10^9)-G31 -> 32.9109 | I31: =10^(H31/10) -> 1954.7444 | J31: =10*LOG10(K31) -> 24.274572 | K31: =1/((1/K27)+(1/I31)) -> 267.58218 | L31: =(2/3)^3*Parámetros!C56*(Parámetros!C57)^2*'No linealidades'!D19*(10^(E31/10)*0.001)^2*LOG10(PI()^2*ABS(Parámetros!C58*10^(-24))*'No linealidades'!D19*(Parámetros!C59)^2*Parámetros!C74^2)/(PI()*ABS(Parámetros!C58*10^(-24))*Parámetros!C74^3)*Parámetros!C73*10^9 -> 0.001332671 | M31: =10*LOG10(N31) -> 28.75277 | N31: =1/L31 -> 750.37273 | O31: =10*LOG10(P31) -> 20.792416 | P31: =HARMEAN(N11,N6,N15,N19,N23,N27,N31)/7 -> 120.01669 | Q31: =10*LOG10(HARMEAN(K31,P31)/2) -> 19.183163
A32: Fibra | B32: 79 | C32: =Parámetros!C41 -> 0.185 | D32: =-B32*C32 -> -14.615 | E32: =D32+E31 -> -9.135 | F32: =IF(E32>=Parámetros!C$33,"V","F") -> V
A33: Aguada Cecilio
A34: VOA (Line In) | D34: =-(E32+Parámetros!H18) -> -9.665 | E34: =D34+E32 -> -18.8 | F34: =Parámetros!C22 -> -18.02
A35: Preamplificador | D35: =Parámetros!C20 -> 21 | E35: =D35+E34 -> 2.2 | G35: =Parámetros!C23 -> 5.5 | H35: =E34+158.9-10*LOG10(Parámetros!C$13*10^9)-G35 -> 33.6309 | I35: =10^(H35/10) -> 2307.2252 | J35: =10*LOG10(K35) -> 23.798024 | K35: =1/((1/K31)+(1/I35)) -> 239.77419 | L35: - | M35: - | N35: - | O35: - | P35: - | Q35: =10*LOG10(HARMEAN(K35,P31)/2) -> 19.029939
A36: DEMUX+ | D36: =-Parámetros!C16 -> -10 | E36: =D36+E35 -> -7.8
A37: Transceiver | E37: =E36 -> -7.8 | F37: =IF(E37>=Parámetros!C67,"V","F") -> V
F38: TOTAL | J38: =J35 -> 23.798024 | K38: =K35 -> 239.77419 | O38: =O31 -> 20.792416 | P38: =P31 -> 120.01669 | Q38: =10*LOG10(HARMEAN(K38,P38)/2) -> 19.029939 | R38: NO FUNCIONA
F39: Requerido para 100 Gbps | J39: =Parámetros!C83 -> 20.5 | K39: =10^(J39/10) -> 112.20185 | Q39: =Parámetros!C83 -> 20.5
A41: Longitud de onda | B41: Coeficiente DC (ps/(nm.km) | C41: Coeficiente DCF (ps/(nm.km) | D41: Compensacion Transceiver ps/nm | H41: Longitud de onda | I41: Coeficiente DC (ps/(nm.km)
...

Sheet Enlace Largo 200Gbps REG
A1: Dina Huapi - Aguada Cecilio | D1: calculos normalizados a 0,1 nm
A2: Presupuesto de Potencia | B2: Distancia (km) | C2: Atenuación por km | D2: Amplificación/Atenuación (dB) | E2: Potencia acumulada (dBm) | F2: 200 Gbps / Limite | G2: NF (dB) | H2: OSNR canal (dB) | I2: OSNR canal (veces) | J2: OSNR acumulada (dB) | K2: OSNR acumulada (veces) | L2: 1/GSNR NL | M2: GSNR NL (dB) | N2: GSNR NL (veces) | O2: GSNR NL acumulada (dB) | P2: GSNR NL acumulada (veces) | Q2: GSNR Total (dB)
A3: Dina Huapi | F3: 200
A4: Transceiver | E4: =Parámetros!C78 -> -9 | H4: =Parámetros!C82 -> 38 | I4: =10^(H4/10) -> 6309.5734 | J4: =H4 -> 38 | K4: =I4 -> 6309.5734 | L4: - | M4: - | N4: - | O4: - | P4: -
A5: MUX+ | D5: =-Parámetros!C16 -> -10 | E5: =D5+E4 -> -19 | F5: =Parámetros!C$29 -> -17.52
A6: Amplificador Booster | D6: =Parámetros!C27 -> 21.5 | E6: =D6+E5 -> 2.5 | G6: =Parámetros!C30 -> 6 | H6: =E5+158.9-10*LOG10(Parámetros!C13*10^9)-G6 -> 32.9309 | I6: =10^(H6/10) -> 1963.7671 | J6: =10*LOG10(K6) -> 31.754091 | K6: =1/((1/K4)+(1/I6)) -> 1497.6457 | L6: =(2/3)^3*Parámetros!C56*(Parámetros!C57)^2*'No linealidades'!D13*(10^(E7/10)*0.001)^2*LOG10(PI()^2*ABS(Parámetros!C58*10^(-24))*'No linealidades'!D13*(Parámetros!C59)^2*Parámetros!C74^2)/(PI()*ABS(Parámetros!C58*10^(-24))*Parámetros!C74^3)*Parámetros!C73*10^9 -> 0.00034721887 | M6: =10*LOG10(N6) -> 34.593967 | N6: =1/L6 -> 2880.0278 | O6: =M6 -> 34.593967 | P6: =N6 -> 2880.0278 | Q6: =10*LOG10(HARMEAN(K6,P6)/2) -> 29.935624
A7: VOA (BOOSTER) | D7: 0 | E7: =E6 -> 2.5
A8: Fibra | B8: 107 | C8: =Parámetros!C41 -> 0.185 | D8: =-B8*C8 -> -19.795 | E8: =D8+E7 -> -17.295 | F8: =IF(E8>=Parámetros!C$33,"V","F") -> V
A9: Comallo
A10: VOA (ILA) | D10: =-(E8-Parámetros!C$37) -> -2.225 | E10: =E8+D10 -> -19.52 | F10: =Parámetros!C$37 -> -19.52
A11: Amplificador (Comallo) | D11: =Parámetros!C$35 -> 25 | E11: =E10+D11 -> 5.48 | G11: =Parámetros!C$38 -> 5.5 | H11: =E10+158.9-10*LOG10(Parámetros!C$13*10^9)-G11 -> 32.9109 | I11: =10^(H11/10) -> 1954.7444 | J11: =10*LOG10(K11) -> 29.283792 | K11: =1/((1/K6)+(1/I11)) -> 847.96749 | L11: =(2/3)^3*Parámetros!C56*(Parámetros!C57)^2*'No linealidades'!D14*(10^(E11/10)*0.001)^2*LOG10(PI()^2*ABS(Parámetros!C58*10^(-24))*'No linealidades'!D14*(Parámetros!C59)^2*Parámetros!C74^2)/(PI()*ABS(Parámetros!C58*10^(-24))*Parámetros!C74^3)*Parámetros!C73*10^9 -> 0.0013588805 | M11: =10*LOG10(N11) -> 28.668187 | N11: =1/L11 -> 735.89989 | O11: =10*LOG10(P11) -> 27.679957 | P11: =HARMEAN(N11,N6)/2 -> 586.13233 | Q11: =10*LOG10(HARMEAN(K11,P11)/2) -> 25.397955
A12: Fibra | B12: 95 | C12: =Parámetros!C41 -> 0.185 | D12: =-B12*C12 -> -17.575 | E12: =D12+E11 -> -12.095 | F12: =IF(E12>=Parámetros!C$33,"V","F") -> V
A13: Ing. Jacobacci
A14: VOA (ILA) | D14: =-(E12-Parámetros!C$37) -> -7.425 | E14: =D14+E12 -> -19.52 | F14: =Parámetros!C$37 -> -19.52
A15: Amplificador (Ing. Jacobacci) | D15: =Parámetros!C$35 -> 25 | E15: =D15+E14 -> 5.48 | G15: =Parámetros!C$38 -> 5.5 | H15: =E14+158.9-10*LOG10(Parámetros!C$13*10^9)-G15 -> 32.9109 | I15: =10^(H15/10) -> 1954.7444 | J15: =10*LOG10(K15) -> 27.718907 | K15: =1/((1/K11)+(1/I15)) -> 591.41281 | L15: =(2/3)^3*Parámetros!C56*(Parámetros!C57)^2*'No linealidades'!D15*(10^(E15/10)*0.001)^2*LOG10(PI()^2*ABS(Parámetros!C58*10^(-24))*'No linealidades'!D15*(Parámetros!C59)^2*Parámetros!C74^2)/(PI()*ABS(Parámetros!C58*10^(-24))*Parámetros!C74^3)*Parámetros!C73*10^9 -> 0.0013279594 | M15: =10*LOG10(N15) -> 28.768152 | N15: =1/L15 -> 753.03509 | O15: =10*LOG10(P15) -> 25.17976 | P15: =HARMEAN(N11,N6,N15)/3 -> 329.59151 | Q15: =10*LOG10(HARMEAN(K15,P15)/2) -> 23.256051
A16: Fibra | B16: 77 | C16: =Parámetros!C41 -> 0.185 | D16: =-B16*C16 -> -14.245 | E16: =D16+E15 -> -8.765 | F16: =IF(E16>=Parámetros!C$33,"V","F") -> V
A17: Maquinchao
A18: VOA (ILA) | D18: =-(E16-Parámetros!C$37) -> -10.755 | E18: =D18+E16 -> -19.52 | F18: =Parámetros!C$37 -> -19.52
A19: Amplificador (Maquinchao) | D19: =Parámetros!C$35 -> 25 | E19: =D19+E18 -> 5.48 | G19: =Parámetros!C$38 -> 5.5 | H19: =E18+158.9-10*LOG10(Parámetros!C$13*10^9)-G19 -> 32.9109 | I19: =10^(H19/10) -> 1954.7444 | J19: =10*LOG10(K19) -> 26.570955 | K19: =1/((1/K15)+(1/I19)) -> 454.04144 | L19: =(2/3)^3*Parámetros!C56*(Parámetros!C57)^2*'No linealidades'!D16*(10^(E19/10)*0.001)^2*LOG10(PI()^2*ABS(Parámetros!C58*10^(-24))*'No linealidades'!D16*(Parámetros!C59)^2*Parámetros!C74^2)/(PI()*ABS(Parámetros!C58*10^(-24))*Parámetros!C74^3)*Parámetros!C73*10^9 -> 0.001320098 | M19: =10*LOG10(N19) -> 28.793938 | N19: =1/L19 -> 757.5195 | O19: =10*LOG10(P19) -> 23.610959 | P19: =HARMEAN(N11,N6,N15,N19)/4 -> 229.66559 | Q19: =10*LOG10(HARMEAN(K19,P19)/2) -> 21.833214
A20: Fibra | B20: 74 | C20: =Parámetros!C41 -> 0.185 | D20: =-B20*C20 -> -13.69 | E20: =D20+E19 -> -8.21 | F20: =IF(E20>=Parámetros!C$33,"V","F") -> V
A21: Los Menucos (Regeneracion)
A22: VOA (Line In) | D22: =-(E20+Parámetros!H18) -> -10.59 | E22: =D22+E20 -> -18.8 | F22: =Parámetros!C22 -> -18.02
A23: Preamplificador | D23: =Parámetros!C20 -> 21 | E23: =D23+E22 -> 2.2 | G23: =Parámetros!C23 -> 5.5 | H23: =E22+158.9-10*LOG10(Parámetros!C13*10^9)-G23 -> 33.6309 | I23: =10^(H23/10) -> 2307.2252 | J23: =10*LOG10(K23) -> 25.790771 | K23: =1/(1/I23+1/K19) -> 379.38236 | L23: - | M23: - | N23: - | O23: - | P23: - | Q23: =10*LOG10(HARMEAN(K22,P19)/2) -> 20.600659
A24: DEMUX+ | D24: =-Parámetros!C16 -> -10 | E24: =D24+E23 -> -7.8
A25: Transceiver (Rx) | E25: =E24 -> -7.8
A26: Transceiver (Tx) | E26: =Parámetros!C78 -> -9 | H26: =Parámetros!C82 -> 38 | I26: =10^(H26/10) -> 6309.5734 | J26: =H26 -> 38 | K26: =10^(J26/10) -> 6309.5734 | L26: - | M26: - | N26: - | O26: - | P26: -
A27: MUX+ | D27: =-Parámetros!C16 -> -10 | E27: =D27+E26 -> -19 | F27: =Parámetros!C29 -> -17.52
A28: Amplificador Booster | D28: =Parámetros!C27 -> 21.5 | E28: =D28+E27 -> 2.5 | G28: =Parámetros!C18 -> -25 | H28: =E27+158.9-10*LOG10(Parámetros!C13*10^9)-G28 -> 63.9309 | I28: =10^(H28/10) -> 2472236.3 | J28: =10*LOG10(K28) -> 37.98893 | K28: =1/((1/K26)+(1/I28)) -> 6293.5113 | L28: =(2/3)^3*Parámetros!C56*(Parámetros!C57)^2*'No linealidades'!D17*(10^(E29/10)*0.001)^2*LOG10(PI()^2*ABS(Parámetros!C58*10^(-24))*'No linealidades'!D17*(Parámetros!C59)^2*Parámetros!C60^2)/(PI()*ABS(Parámetros!C58*10^(-24))*Parámetros!C60^3)*Parámetros!C86*10^9 -> 4.9935018e-05 | M28: =10*LOG10(N28) -> 43.015948 | N28: =1/L28 -> 20026.027 | O28: =10*LOG10(P28) -> 43.015948 | P28: =N28 -> 20026.027 | Q28: =10*LOG10(HARMEAN(K28,P28)/2) -> 36.802095
A29: VOA (Booster) | D29: 0 | E29: =E28 -> 2.5
A30: Fibra | B30: 96 | C30: =Parámetros!C41 -> 0.185 | D30: =-B30*C30 -> -17.76 | E30: =D30+E29 -> -15.26 | F30: =IF(E30>=Parámetros!C$33,"V","F") -> V
A31: MinistroRamosMexia
A32: VOA (ILA) | D32: =-(E30-Parámetros!C$37) -> -4.26 | E32: =D32+E30 -> -19.52 | F32: =Parámetros!C$37 -> -19.52
A33: Amplificador (Nahuel Niyeu) | D33: =Parámetros!C$35 -> 25 | E33: =D33+E32 -> 5.48 | G33: =Parámetros!C$38 -> 5.5 | H33: =E32+158.9-10*LOG10(Parámetros!C$13*10^9)-G33 -> 32.9109 | I33: =10^(H33/10) -> 1954.7444 | J33: =10*LOG10(K33) -> 31.736209 | K33: =1/((1/K28)+(1/I33)) -> 1491.4919 | L33: =(2/3)^3*Parámetros!C56*(Parámetros!C57)^2*'No linealidades'!D18*(10^(E33/10)*0.001)^2*LOG10(PI()^2*ABS(Parámetros!C58*10^(-24))*'No linealidades'!D18*(Parámetros!C59)^2*Parámetros!C74^2)/(PI()*ABS(Parámetros!C58*10^(-24))*Parámetros!C74^3)*Parámetros!C73*10^9 -> 0.0012853467 | M33: =10*LOG10(N33) -> 28.909797 | N33: =1/L33 -> 778.00024 | O33: =10*LOG10(P33) -> 28.744271 | P33: =HARMEAN(N28,N33)/2 -> 748.90566 | Q33: =10*LOG10(HARMEAN(K33,P33)/2) -> 26.977229
A34: Fibra | B34: 64 | C34: =Parámetros!C41 -> 0.185 | D34: =-B34*C34 -> -11.84 | E34: =D34+E33 -> -6.36 | F34: =IF(E34>=Parámetros!C$33,"V","F") -> V
A35: Nahuel Niyeu
A36: VOA (ILA) | D36: =-(E34-Parámetros!C$37) -> -13.16 | E36: =D36+E34 -> -19.52 | F36: =Parámetros!C$37 -> -19.52
A37: Amplificador (Nahuel Niyeu) | D37: =Parámetros!C$35 -> 25 | E37: =D37+E36 -> 5.48 | G37: =Parámetros!C$38 -> 5.5 | H37: =E36+158.9-10*LOG10(Parámetros!C$13*10^9)-G37 -> 32.9109 | I37: =10^(H37/10) -> 1954.7444 | J37: =10*LOG10(K37) -> 29.273658 | K37: =1/((1/K33)+(1/I37)) -> 845.99115 | L37: =(2/3)^3*Parámetros!C56*(Parámetros!C57)^2*'No linealidades'!D19*(10^(E37/10)*0.001)^2*LOG10(PI()^2*ABS(Parámetros!C58*10^(-24))*'No linealidades'!D19*(Parámetros!C59)^2*Parámetros!C74^2)/(PI()*ABS(Parámetros!C58*10^(-24))*Parámetros!C74^3)*Parámetros!C73*10^9 -> 0.001332671 | M37: =10*LOG10(N37) -> 28.75277 | N37: =1/L37 -> 750.37273 | O37: =10*LOG10(P37) -> 25.738219 | P37: =HARMEAN(N28,N33,N37)/3 -> 374.81924 | Q37: =10*LOG10(HARMEAN(K37,P37)/2) -> 24.145395
A38: Fibra | B38: 79 | C38: =Parámetros!C41 -> 0.185 | D38: =-B38*C38 -> -14.615 | E38: =D38+E33 -> -9.135 | F38: =IF(E38>=Parámetros!C$33,"V","F") -> V
A39: Aguada Cecilio
A40: VOA (Line In) | D40: =-(E38+Parámetros!H18) -> -9.665 | E40: =D40+E38 -> -18.8 | F40: =Parámetros!C22 -> -18.02
...
